<?xml version ="1.0"?>
<robot name="my_robot">
    <material name="green">
        <color rgba ="0 0.7 0 1"/>
    </material>

    <material name="white">
        <color rgba ="1 1 1 1"/>
    </material>

    <link name="base_link">
        <visual>
            <geometry>
                <box size="0.6 0.4 0.2" />
            </geometry>
            <origin xyz = "0 0 0.1" rpy = "0 0 0" />
            <material name="green"/>
        </visual>
    </link>

    <link name="wheel_front_left">
        <visual>
            <geometry>
                <cylinder radius="0.1" length="0.05"/> 
            </geometry>
            <origin xyz="0 0 0" rpy="1.57 0 0"/>
            <material name="red"/>
        </visual>
    </link>

    <link name="wheel_front_right">
        <visual>
            <geometry>
                <cylinder radius="0.1" length="0.05"/> 
            </geometry>
            <origin xyz="0 0 0" rpy="1.57 0 0"/>
            <material name="red"/>
        </visual>
    </link>

    <link name="wheel_rear_left">
        <visual>
            <geometry>
                <cylinder radius="0.1" length="0.05"/> 
            </geometry>
            <origin xyz="0 0 0" rpy="1.57 0 0"/>
            <material name="red"/>
        </visual>
    </link>

    <link name="wheel_rear_right">
        <visual>
            <geometry>
                <cylinder radius="0.1" length="0.05"/> 
            </geometry>
            <origin xyz="0 0 0" rpy="1.57 0 0"/>
            <material name="red"/>
        </visual>
    </link>

    <link name="camera">
        <visual>
            <geometry>
                <box size = "0.1 0.1 0.1"/> 
            </geometry>
            <origin xyz="0 0 0.25" rpy="0 0 0"/>
            <material name="white"/>
        </visual>
    </link>

    <link name="lense">
        <visual>
            <geometry>
                <cylinder radius="0.05" length="0.05"/> 
            </geometry>
            <origin xyz="0.05 0 0.25" rpy="0 1.57 0"/>
            <material name="white"/>
        </visual>
    </link>

    <joint name="base_wheel_joint_front_left" type="continuous">
        <parent link="base_link"/>
        <child link="wheel_front_left"/>
        <origin xyz="-0.15 0.225 0" rpy="0 0 0"/>
        <axis xyz="0 1 0"/>
    </joint>

    <joint name="base_wheel_joint_front_right" type="continuous">
        <parent link="base_link"/>
        <child link="wheel_front_right"/>
        <origin xyz="-0.15 -0.225 0" rpy="0 0 0"/>
        <axis xyz="0 1 0"/>
    </joint>

    <joint name="base_wheel_joint_rear_left" type="continuous">
        <parent link="base_link"/>
        <child link="wheel_rear_left"/>
        <origin xyz="0.15 0.225 0" rpy="0 0 0"/>
        <axis xyz="0 1 0"/>
    </joint>

    <joint name="base_wheel_joint_rear_right" type="continuous">
        <parent link="base_link"/>
        <child link="wheel_rear_right"/>
        <origin xyz="0.15 -0.225 0" rpy="0 0 0"/>
        <axis xyz="0 1 0"/>
    </joint>

    <joint name="base_camera" type="fixed">
        <parent link="base_link"/>
        <child link="camera"/>
        <origin xyz="0 0 0" rpy="0 0 0"/>
        <axis xyz="0 1 0"/>
    </joint>

    <joint name="camera_lense" type="fixed">
        <parent link="camera"/>
        <child link="lense"/>
        <origin xyz="0 0 0" rpy="0 0 0"/>
        <axis xyz="0 1 0"/>
    </joint>

</robot>